Traceback (most recent call last):
  File "C:\Users\vance\.conda\envs\spatial\Lib\site-packages\jupyter_cache\executors\utils.py", line 58, in single_nb_execution
    executenb(
  File "C:\Users\vance\.conda\envs\spatial\Lib\site-packages\nbclient\client.py", line 1314, in execute
    return NotebookClient(nb=nb, resources=resources, km=km, **kwargs).execute()
           ^^^^^^^^^^^^^^^^^^^^^^^^^^^^^^^^^^^^^^^^^^^^^^^^^^^^^^^^^^^^^^^^^^^^^
  File "C:\Users\vance\.conda\envs\spatial\Lib\site-packages\jupyter_core\utils\__init__.py", line 165, in wrapped
    return loop.run_until_complete(inner)
           ^^^^^^^^^^^^^^^^^^^^^^^^^^^^^^
  File "C:\Users\vance\.conda\envs\spatial\Lib\asyncio\base_events.py", line 687, in run_until_complete
    return future.result()
           ^^^^^^^^^^^^^^^
  File "C:\Users\vance\.conda\envs\spatial\Lib\site-packages\nbclient\client.py", line 709, in async_execute
    await self.async_execute_cell(
  File "C:\Users\vance\.conda\envs\spatial\Lib\site-packages\nbclient\client.py", line 1062, in async_execute_cell
    await self._check_raise_for_error(cell, cell_index, exec_reply)
  File "C:\Users\vance\.conda\envs\spatial\Lib\site-packages\nbclient\client.py", line 918, in _check_raise_for_error
    raise CellExecutionError.from_cell_and_msg(cell, exec_reply_content)
nbclient.exceptions.CellExecutionError: An error occurred while executing the following cell:
------------------
# Convert the concatenated markdown content to a PDF file
convert_markdown_to_pdf(markdown_content, output_pdf)

print(f"PDF created successfully: {output_pdf}")
------------------


[1;31m---------------------------------------------------------------------------[0m
[1;31mRuntimeError[0m                              Traceback (most recent call last)
Cell [1;32mIn[6], line 2[0m
[0;32m      1[0m [38;5;66;03m# Convert the concatenated markdown content to a PDF file[39;00m
[1;32m----> 2[0m [43mconvert_markdown_to_pdf[49m[43m([49m[43mmarkdown_content[49m[43m,[49m[43m [49m[43moutput_pdf[49m[43m)[49m
[0;32m      4[0m [38;5;28mprint[39m([38;5;124mf[39m[38;5;124m"[39m[38;5;124mPDF created successfully: [39m[38;5;132;01m{[39;00moutput_pdf[38;5;132;01m}[39;00m[38;5;124m"[39m)

Cell [1;32mIn[3], line 17[0m, in [0;36mconvert_markdown_to_pdf[1;34m(markdown_content, output_file)[0m
[0;32m     15[0m [38;5;28;01mdef[39;00m [38;5;21mconvert_markdown_to_pdf[39m(markdown_content, output_file):
[0;32m     16[0m [38;5;250m    [39m[38;5;124;03m"""Convert markdown content to a PDF file."""[39;00m
[1;32m---> 17[0m     [43mpypandoc[49m[38;5;241;43m.[39;49m[43mconvert_text[49m[43m([49m[43mmarkdown_content[49m[43m,[49m[43m [49m[38;5;124;43m'[39;49m[38;5;124;43mpdf[39;49m[38;5;124;43m'[39;49m[43m,[49m
[0;32m     18[0m [43m                          [49m[38;5;28;43mformat[39;49m[38;5;241;43m=[39;49m[38;5;124;43m'[39;49m[38;5;124;43mmd[39;49m[38;5;124;43m'[39;49m[43m,[49m[43m [49m[43moutputfile[49m[38;5;241;43m=[39;49m[43moutput_file[49m[43m)[49m

File [1;32m~\.conda\envs\spatial\Lib\site-packages\pypandoc\__init__.py:92[0m, in [0;36mconvert_text[1;34m(source, to, format, extra_args, encoding, outputfile, filters, verify_format, sandbox, cworkdir)[0m
[0;32m     58[0m [38;5;250m[39m[38;5;124;03m"""Converts given `source` from `format` to `to`.[39;00m
[0;32m     59[0m 
[0;32m     60[0m [38;5;124;03m:param str source: Unicode string or bytes (see encoding)[39;00m
[1;32m   (...)[0m
[0;32m     89[0m [38;5;124;03m        path.[39;00m
[0;32m     90[0m [38;5;124;03m"""[39;00m
[0;32m     91[0m source [38;5;241m=[39m _as_unicode(source, encoding)
[1;32m---> 92[0m [38;5;28;01mreturn[39;00m [43m_convert_input[49m[43m([49m[43msource[49m[43m,[49m[43m [49m[38;5;28;43mformat[39;49m[43m,[49m[43m [49m[38;5;124;43m'[39;49m[38;5;124;43mstring[39;49m[38;5;124;43m'[39;49m[43m,[49m[43m [49m[43mto[49m[43m,[49m[43m [49m[43mextra_args[49m[38;5;241;43m=[39;49m[43mextra_args[49m[43m,[49m
[0;32m     93[0m [43m                      [49m[43moutputfile[49m[38;5;241;43m=[39;49m[43moutputfile[49m[43m,[49m[43m [49m[43mfilters[49m[38;5;241;43m=[39;49m[43mfilters[49m[43m,[49m
[0;32m     94[0m [43m                      [49m[43mverify_format[49m[38;5;241;43m=[39;49m[43mverify_format[49m[43m,[49m[43m [49m[43msandbox[49m[38;5;241;43m=[39;49m[43msandbox[49m[43m,[49m
[0;32m     95[0m [43m                      [49m[43mcworkdir[49m[38;5;241;43m=[39;49m[43mcworkdir[49m[43m)[49m

File [1;32m~\.conda\envs\spatial\Lib\site-packages\pypandoc\__init__.py:467[0m, in [0;36m_convert_input[1;34m(source, format, input_type, to, extra_args, outputfile, filters, verify_format, sandbox, cworkdir)[0m
[0;32m    465[0m [38;5;66;03m# check that pandoc returned successfully[39;00m
[0;32m    466[0m [38;5;28;01mif[39;00m p[38;5;241m.[39mreturncode [38;5;241m!=[39m [38;5;241m0[39m:
[1;32m--> 467[0m     [38;5;28;01mraise[39;00m [38;5;167;01mRuntimeError[39;00m(
[0;32m    468[0m         [38;5;124m'[39m[38;5;124mPandoc died with exitcode [39m[38;5;124m"[39m[38;5;132;01m%s[39;00m[38;5;124m"[39m[38;5;124m during conversion: [39m[38;5;132;01m%s[39;00m[38;5;124m'[39m [38;5;241m%[39m (p[38;5;241m.[39mreturncode, stderr)
[0;32m    469[0m     )
[0;32m    471[0m [38;5;66;03m# if there is output on stderr, process it and send to logger[39;00m
[0;32m    472[0m [38;5;28;01mif[39;00m stderr:

[1;31mRuntimeError[0m: Pandoc died with exitcode "64" during conversion: YAML parse exception at line 2, column 4:
mapping values are not allowed in this context


